Workbook

Sheet Rebates
B1: META Q1 | C1: Q1 | D1: % CUMPLIMIENTO | E1: % REBATE | F1: REBATE ESPERADO $ | G1: META Q2 | H1: Q2 | I1: % CUMPLIMIENTO | J1: % REBATE | K1: REBATE ESPERADO $ | L1: META Q3 | M1: Q3 | N1: % CUMPLIMIENTO | O1: % REBATE | P1: REBATE ESPERADO $ | Q1: META Q4 | R1: Q4 | S1: % CUMPLIMIENTO | T1: % REBATE | U1: REBATE ESPERADO $
A2: INDUSTRIAL | B2: 80000000 | C2: =Tablas!K3 -> 13884841 | D2: =Tablas!L3 -> 0.17356052 | E2: =IF(D2<100%,0%,IF(AND(D2>=100%,D2<110%),100%,IF(AND(D2>=110%,D2<120%),130%,150%))) -> 0 | F2: =IF(E2=100%,C2*0.04,IF(E2=130%,C2*0.052,IF(E2=150%,C2*0.06,0))) -> 0 | G2: 100000000 | H2: =Tablas!K8 -> 1.1201431e+08 | I2: =Tablas!L8 -> 1.1201431 | J2: =IF(I2<100%,0%,IF(AND(I2>=100%,I2<110%),100%,IF(AND(I2>=110%,I2<120%),130%,150%))) -> 1.3 | K2: =IF(J2=100%,H2*0.04,IF(J2=130%,H2*0.052,IF(J2=150%,H2*0.06,0))) -> 5824744.3 | L2: 120000000 | M2: =Tablas!K13 -> 53318323 | N2: =Tablas!L13 -> 0.44431936 | O2: =IF(N2<100%,0%,IF(AND(N2>=100%,N2<110%),100%,IF(AND(N2>=110%,N2<120%),130%,150%))) -> 0 | P2: =IF(O2=100%,M2*0.04,IF(O2=130%,M2*0.052,IF(O2=150%,M2*0.06,0))) -> 0 | Q2: 100000000 | R2: =Tablas!K18 -> 0 | S2: =Tablas!L18 -> 0 | T2: =IF(S2<100%,0%,IF(AND(S2>=100%,S2<110%),100%,IF(AND(S2>=110%,S2<120%),130%,150%))) -> 0 | U2: =IF(T2=100%,R2*0.04,IF(T2=130%,R2*0.055,IF(T2=150%,R2*0.065,0))) -> 0
A3: ELECTROBARRAS Y TRAFOS | B3: 200000000 | C3: =Tablas!K24 -> 53061866 | D3: =Tablas!L24 -> 0.26530933 | E3: =IF(D3<100%,0%,IF(AND(D3>=100%,D3<110%),100%,IF(AND(D3>=110%,D3<120%),130%,150%))) -> 0 | F3: =IF(E3=100%,Tablas!M24*0.04,IF(E3=130%,Tablas!M24*0.052,IF(E3=150%,Tablas!M24*0.06,0))) -> 0 | G3: 200000000 | H3: =Tablas!K29 -> 88173290 | I3: =Tablas!L29 -> 0.44086645 | J3: =IF(I3<100%,0%,IF(AND(I3>=100%,I3<110%),100%,IF(AND(I3>=110%,I3<120%),130%,150%))) -> 0 | K3: =IF(J3=100%,Tablas!M29*0.04,IF(J3=130%,Tablas!M29*0.052,IF(J3=150%,Tablas!M29*0.06,0))) -> 0 | L3: 200000000 | M3: =Tablas!K34 -> 5.7456746e+08 | N3: =Tablas!L34 -> 2.8728373 | O3: =IF(N3<100%,0%,IF(AND(N3>=100%,N3<110%),100%,IF(AND(N3>=110%,N3<120%),130%,150%))) -> 1.5 | P3: =IF(O3=100%,Tablas!M34*0.04,IF(O3=130%,Tablas!M34*0.052,IF(O3=150%,Tablas!M34*0.06,0))) -> 108637.82 | Q3: 200000000 | R3: =Tablas!K39 -> 0 | S3: =Tablas!L39 -> 0 | T3: =IF(S3<100%,0%,IF(AND(S3>=100%,S3<110%),100%,IF(AND(S3>=110%,S3<120%),130%,150%))) -> 0 | U3: =IF(T3=100%,Tablas!M39*0.04,IF(T3=130%,Tablas!M39*0.052,IF(T3=150%,Tablas!M39*0.06,0))) -> 0
A4: DC & DC | B4: 2720000000 | C4: =Tablas!K45 -> 2.7447781e+09 | D4: =Tablas!L45 -> 1.0091096 | E4: =IF(D4<100%,0%,IF(AND(D4>=100%,D4<110%),100%,IF(AND(D4>=110%,D4<120%),130%,150%))) -> 1 | F4: =IF(E4=100%,C4*0.05,IF(E4=130%,C4*0.065,IF(E4=150%,C4*0.075,0))) -> 1.372389e+08 | G4: 3400000000 | H4: =Tablas!K50 -> 4.231388e+09 | I4: =Tablas!L50 -> 1.2445259 | J4: =IF(I4<100%,0%,IF(AND(I4>=100%,I4<110%),100%,IF(AND(I4>=110%,I4<120%),130%,150%))) -> 1.5 | K4: =IF(J4=100%,H4*0.05,IF(J4=130%,H4*0.065,IF(J4=150%,H4*0.075,0))) -> 3.173541e+08 | L4: 4080000000 | M4: =Tablas!K55 -> 4.0293133e+08 | N4: =Tablas!L55 -> 0.09875768 | O4: =IF(N4<100%,0%,IF(AND(N4>=100%,N4<110%),100%,IF(AND(N4>=110%,N4<120%),130%,150%))) -> 0 | P4: =IF(O4=100%,M4*0.05,IF(O4=130%,M4*0.065,IF(O4=150%,M4*0.075,0))) -> 0 | Q4: 3400000000 | R4: =Tablas!K60 -> 0 | S4: =Tablas!L60 -> 0 | T4: =IF(S4<100%,0%,IF(AND(S4>=100%,S4<110%),100%,IF(AND(S4>=110%,S4<120%),130%,150%))) -> 0 | U4: =IF(T4=100%,R4*0.05,IF(T4=130%,R4*0.065,IF(T4=150%,R4*0.075,0))) -> 0

Sheet Tablas
A2: INDUSTRIAL | C2: MES | D2: META | E2: COMPRADO | F2: FACTURADO | G2: FACTURADO ANTERIOR | H2: FACTURADO Q | I2: PTE x FACTURAR | J2: BACK ORDER | K2: TOTAL Q1 | L2: % CUMPLIMIENTO Q1
B3: Q1 | C3: ENERO | D3: 26666667 | E3: =SUMIFS(Compras!N:N,Compras!G:G,$A$2,Compras!D:D,C3) -> 506970 | F3: =SUMIFS(Facturado!Q:Q,Facturado!K:K,$A$2,Facturado!C:C,C3) -> 2099486.6 | G3: =IF(E3=0,F3,SUMIFS(Facturado!Q:Q,Facturado!K:K,$A$2,Facturado!C:C,C3,Facturado!H:H,"SI")) -> 1592516.8 | H3: =F3-G3 -> 506969.75 | I3: =IF(H3<E3,E3-H3,0) -> 0.25 | J3: =I3+I4 -> 0.25 | K3: =IF(F6<D6,(F6+J3),F6) -> 13884841 | L3: =IFERROR(((K3/D6)*100)/100,0) -> 0.17356052
C4: FEBRERO | D4: 26666667 | E4: =SUMIFS(Compras!N:N,Compras!G:G,$A$2,Compras!D:D,C4) -> 1462586.7 | F4: =SUMIFS(Facturado!Q:Q,Facturado!K:K,$A$2,Facturado!C:C,C4) -> 1680300 | G4: =IF(E4=0,F4,SUMIFS(Facturado!Q:Q,Facturado!K:K,$A$2,Facturado!C:C,C4,Facturado!H:H,"SI")) -> 0 | H4: =F4-G4 -> 1680300 | I4: =IF(H4<E4,E4-H4,0) -> 0
C5: MARZO | D5: 26666667 | E5: =SUMIFS(Compras!N:N,Compras!G:G,$A$2,Compras!D:D,C5) -> 18431231 | F5: =SUMIFS(Facturado!Q:Q,Facturado!K:K,$A$2,Facturado!C:C,C5) -> 10105054 | G5: =IF(E5=0,F5,SUMIFS(Facturado!Q:Q,Facturado!K:K,$A$2,Facturado!C:C,C5,Facturado!H:H,"SI")) -> 0 | H5: =F5-G5 -> 10105054
C6: TOTALES | D6: =SUM(D3:D5) -> 80000000 | F6: =SUM(F3:F5) -> 13884841
C7: MES | D7: META | E7: COMPRADO | F7: FACTURADO | G7: FACTURADO ANTERIOR | H7: FACTURADO Q | I7: PTE x FACTURAR | J7: BACK ORDER | K7: TOTAL Q2 | L7: % CUMPLIMIENTO Q2
B8: Q2 | C8: ABRIL | D8: =33333333 -> 33333333 | E8: =SUMIFS(Compras!N:N,Compras!G:G,$A$2,Compras!D:D,C8) -> 57100650 | F8: =SUMIFS(Facturado!Q:Q,Facturado!K:K,$A$2,Facturado!C:C,C8) -> 56933765 | G8: =IF(E8=0,F8,SUMIFS(Facturado!Q:Q,Facturado!K:K,$A$2,Facturado!C:C,C8,Facturado!I:I,"<>Q2")) -> 4805120 | H8: =F8-G8 -> 52128645 | I8: =IF(H8<E8,E8-H8,0) -> 4972005 | J8: =I8+I9 -> 67454960 | K8: =IF(F11<D11,(F11+J8),F11) -> 1.1201431e+08 | L8: =IFERROR(((K8/D11)*100)/100,0) -> 1.1201431
C9: MAYO | D9: =33333333 -> 33333333 | E9: =SUMIFS(Compras!N:N,Compras!G:G,$A$2,Compras!D:D,C9) -> 72183238 | F9: =SUMIFS(Facturado!Q:Q,Facturado!K:K,$A$2,Facturado!C:C,C9) -> 18658434 | G9: =IF(E9=0,F9,SUMIFS(Facturado!Q:Q,Facturado!K:K,$A$2,Facturado!C:C,C9,Facturado!I:I,"<>Q2")) -> 8958150.4 | H9: =F9-G9 -> 9700283.2 | I9: =IF(H9<E9,E9-H9,0) -> 62482955
C10: JUNIO | D10: =33333334 -> 33333334 | E10: =SUMIFS(Compras!N:N,Compras!G:G,$A$2,Compras!D:D,C10) -> 10017000 | F10: =SUMIFS(Facturado!Q:Q,Facturado!K:K,$A$2,Facturado!C:C,C10) -> 36422115 | G10: =IF(E10=0,F10,SUMIFS(Facturado!Q:Q,Facturado!K:K,$A$2,Facturado!C:C,C10,Facturado!I:I,"<>Q2")) -> 5647703.4 | H10: =F10-G10 -> 30774412
C11: TOTALES | D11: =SUM(D8:D10) -> 100000000 | F11: =SUM(F8:F10) -> 1.1201431e+08
C12: MES | D12: META | E12: COMPRADO | F12: FACTURADO | G12: FACTURADO ANTERIOR | H12: FACTURADO Q | I12: PTE x FACTURAR | J12: BACK ORDER | K12: TOTAL Q3 | L12: % CUMPLIMIENTO Q3
B13: Q3 | C13: JULIO | D13: 40000000 | E13: =SUMIFS(Compras!N:N,Compras!G:G,$A$2,Compras!D:D,C13) -> 6255743 | F13: =SUMIFS(Facturado!Q:Q,Facturado!K:K,$A$2,Facturado!C:C,C13) -> 41312985 | G13: =IF(E13=0,F13,SUMIFS(Facturado!Q:Q,Facturado!K:K,$A$2,Facturado!C:C,C13,Facturado!I:I,"<>Q3")) -> 40848900 | H13: =F13-G13 -> 464084.88 | I13: =IF(H13<E13,E13-H13,0) -> 5791658.1 | J13: =I13+I14 -> 5791658.1 | K13: =IF(F16<D16,(F16+J13),F16) -> 53318323 | L13: =IFERROR(((K13/D16)*100)/100,0) -> 0.44431936
C14: AGOSTO | D14: 40000000 | E14: =SUMIFS(Compras!N:N,Compras!G:G,$A$2,Compras!D:D,C14) -> 0 | F14: =SUMIFS(Facturado!Q:Q,Facturado!K:K,$A$2,Facturado!C:C,C14) -> 6213679.8 | G14: =IF(E14=0,F14,SUMIFS(Facturado!Q:Q,Facturado!K:K,$A$2,Facturado!C:C,C14,Facturado!I:I,"<>Q3")) -> 6213679.8 | H14: =F14-G14 -> 0 | I14: =IF(H14<E14,E14-H14,0) -> 0
C15: SEPTIEMBRE | D15: 40000000 | E15: =SUMIFS(Compras!N:N,Compras!G:G,$A$2,Compras!D:D,C15) -> 0 | F15: =SUMIFS(Facturado!Q:Q,Facturado!K:K,$A$2,Facturado!C:C,C15) -> 0 | G15: =IF(E15=0,F15,SUMIFS(Facturado!Q:Q,Facturado!K:K,$A$2,Facturado!C:C,C15,Facturado!I:I,"<>Q3")) -> 0 | H15: =F15-G15 -> 0
C16: TOTALES | D16: =SUM(D13:D15) -> 120000000 | F16: =SUM(F13:F15) -> 47526665
C17: MES | D17: META | E17: COMPRADO | F17: FACTURADO | G17: FACTURADO ANTERIOR | H17: FACTURADO Q | I17: PTE x FACTURAR | J17: BACK ORDER | K17: TOTAL Q4 | L17: % CUMPLIMIENTO Q4
B18: Q4 | C18: OCTUBRE | D18: =33333333 -> 33333333 | E18: =SUMIFS(Compras!N:N,Compras!G:G,$A$2,Compras!D:D,C18) -> 0 | F18: =SUMIFS(Facturado!Q:Q,Facturado!K:K,$A$2,Facturado!C:C,C18) -> 0 | G18: =IF(E18=0,F18,SUMIFS(Facturado!Q:Q,Facturado!K:K,$A$2,Facturado!C:C,C18,Facturado!I:I,"<>Q4")) -> 0 | H18: =F18-G18 -> 0 | I18: =IF(H18<E18,E18-H18,0) -> 0 | J18: =I18+I19 -> 0 | K18: =IF(F21<D21,(F21+J18),F21) -> 0 | L18: =IFERROR(((K18/D21)*100)/100,0) -> 0
C19: NOVIEMBRE | D19: =33333333 -> 33333333 | E19: =SUMIFS(Compras!N:N,Compras!G:G,$A$2,Compras!D:D,C19) -> 0 | F19: =SUMIFS(Facturado!Q:Q,Facturado!K:K,$A$2,Facturado!C:C,C19) -> 0 | G19: =IF(E19=0,F19,SUMIFS(Facturado!Q:Q,Facturado!K:K,$A$2,Facturado!C:C,C19,Facturado!I:I,"<>Q4")) -> 0 | H19: =F19-G19 -> 0 | I19: =IF(H19<E19,E19-H19,0) -> 0
C20: DICIEMBRE | D20: =33333334 -> 33333334 | E20: =SUMIFS(Compras!N:N,Compras!G:G,$A$2,Compras!D:D,C20) -> 0 | F20: =SUMIFS(Facturado!Q:Q,Facturado!K:K,$A$2,Facturado!C:C,C20) -> 0 | G20: =IF(E20=0,F20,SUMIFS(Facturado!Q:Q,Facturado!K:K,$A$2,Facturado!C:C,C20,Facturado!I:I,"<>Q4")) -> 0 | H20: =F20-G20 -> 0
C21: TOTALES | D21: =SUM(D18:D20) -> 100000000 | F21: =SUM(F18:F20) -> 0
A23: ELECTROBARRAS | C23: MES | D23: META | E23: COMPRADO | F23: FACTURADO | G23: FACTURADO ANTERIOR | H23: FACTURADO Q | I23: PTE x FACTURAR | J23: BACK ORDER | K23: TOTAL Q1 | L23: % CUMPLIMIENTO Q1 | M23: TOTAL ELECTROBARRAS Q1
B24: Q1 | C24: ENERO | D24: 66666666 | E24: =SUMIFS(Compras!N:N,Compras!G:G,$A$23,Compras!D:D,C24) -> 0 | F24: =SUMIFS(Facturado!Q:Q,Facturado!K:K,$A$23,Facturado!C:C,C24) -> 3600250.4 | G24: =IF(E24=0,F24,SUMIFS(Facturado!Q:Q,Facturado!K:K,$A$23,Facturado!C:C,C24,Facturado!H:H,"SI")) -> 3600250.4 | H24: =F24-G24 -> 0 | I24: =IF(H24<E24,E24-H24,0) -> 0 | J24: =I24+I25 -> 0 | K24: =IF(F27<D27,(F27+J24),F27) -> 53061866 | L24: =IFERROR(((K24/D27)*100)/100,0) -> 0.26530933 | M24: =SUMIFS(Facturado!Q:Q,Facturado!L:L,$A$23,Facturado!D:D,B24) -> 53061866
C25: FEBRERO | D25: 66666666 | E25: =SUMIFS(Compras!N:N,Compras!G:G,$A$23,Compras!D:D,C25) -> 0 | F25: =SUMIFS(Facturado!Q:Q,Facturado!K:K,$A$23,Facturado!C:C,C25) -> 48735395 | G25: =IF(E25=0,F25,SUMIFS(Facturado!Q:Q,Facturado!K:K,$A$23,Facturado!C:C,C25,Facturado!H:H,"SI")) -> 48735395 | H25: =F25-G25 -> 0 | I25: =IF(H25<E25,E25-H25,0) -> 0
C26: MARZO | D26: 66666668 | E26: =SUMIFS(Compras!N:N,Compras!G:G,$A$23,Compras!D:D,C26) -> 0 | F26: =SUMIFS(Facturado!Q:Q,Facturado!K:K,$A$23,Facturado!C:C,C26) -> 726221.01 | G26: =IF(E26=0,F26,SUMIFS(Facturado!Q:Q,Facturado!K:K,$A$23,Facturado!C:C,C26,Facturado!H:H,"SI")) -> 726221.01 | H26: =F26-G26 -> 0
C27: TOTALES | D27: =SUM(D24:D26) -> 200000000 | F27: =SUM(F24:F26) -> 53061866
C28: MES | D28: META | E28: COMPRADO | F28: FACTURADO | G28: FACTURADO ANTERIOR | H28: FACTURADO Q | I28: PTE x FACTURAR | J28: BACK ORDER | K28: TOTAL Q2 | L28: % CUMPLIMIENTO Q1 | M28: TOTAL ELECTROBARRAS Q2
B29: Q2 | C29: ABRIL | D29: 66666666 | E29: =SUMIFS(Compras!N:N,Compras!G:G,$A$23,Compras!D:D,C29) -> 0 | F29: =SUMIFS(Facturado!Q:Q,Facturado!K:K,$A$23,Facturado!C:C,C29) -> 38949827 | G29: =IF(E29=0,F29,SUMIFS(Facturado!Q:Q,Facturado!K:K,$A$2,Facturado!C:C,C29,Facturado!H:H,"SI",Facturado!D:D,"Q1")) -> 38949827 | H29: =F29-G29 -> 0 | I29: =IF(H29<E29,E29-H29,0) -> 0 | J29: =I29+I30 -> 0 | K29: =IF(F32<D32,(F32+J29),F32) -> 88173290 | L29: =IFERROR(((K29/D32)*100)/100,0) -> 0.44086645 | M29: =SUMIFS(Facturado!Q:Q,Facturado!L:L,$A$23,Facturado!D:D,B29) -> 38949827
C30: MAYO | D30: 66666666 | E30: =SUMIFS(Compras!N:N,Compras!G:G,$A$23,Compras!D:D,C30) -> 0 | F30: =SUMIFS(Facturado!Q:Q,Facturado!K:K,$A$23,Facturado!C:C,C30) -> 0 | G30: =IF(E30=0,F30,SUMIFS(Facturado!Q:Q,Facturado!K:K,$A$23,Facturado!C:C,C30,Facturado!H:H,"SI")) -> 0 | H30: =F30-G30 -> 0 | I30: =IF(H30<E30,E30-H30,0) -> 0
C31: JUNIO | D31: 66666668 | E31: =SUMIFS(Compras!N:N,Compras!G:G,$A$23,Compras!D:D,C31) -> 0 | F31: =SUMIFS(Facturado!Q:Q,Facturado!K:K,$A$23,Facturado!C:C,C31) -> 49223463 | G31: =IF(E31=0,F31,SUMIFS(Facturado!Q:Q,Facturado!K:K,$A$23,Facturado!C:C,C31,Facturado!H:H,"SI")) -> 49223463 | H31: =F31-G31 -> 0
C32: TOTALES | D32: =SUM(D29:D31) -> 200000000 | F32: =SUM(F29:F31) -> 88173290
C33: MES | D33: META | E33: COMPRADO | F33: FACTURADO | G33: FACTURADO ANTERIOR | H33: FACTURADO Q | I33: PTE x FACTURAR | J33: BACK ORDER | K33: TOTAL Q3 | L33: % CUMPLIMIENTO Q1 | M33: TOTAL ELECTROBARRAS Q3
B34: Q3 | C34: JULIO | D34: 66666666 | E34: =SUMIFS(Compras!N:N,Compras!G:G,$A$23,Compras!D:D,C34) -> 49223463 | F34: =SUMIFS(Facturado!Q:Q,Facturado!K:K,$A$23,Facturado!C:C,C34) -> 0 | G34: =IF(E34=0,F34,SUMIFS(Facturado!Q:Q,Facturado!K:K,$A$23,Facturado!C:C,C34,Facturado!H:H,"SI")) -> 0 | H34: =F34-G34 -> 0 | I34: =IF(H34<E34,E34-H34,0) -> 49223463 | J34: =I34+I35 -> 572756833 | K34: =IF(F37<D37,(F37+J34),F37) -> 5.7456746e+08 | L34: =IFERROR(((K34/D37)*100)/100,0) -> 2.8728373 | M34: =SUMIFS(Facturado!Q:Q,Facturado!L:L,$A$23,Facturado!D:D,B34) -> 1810630.2
C35: AGOSTO | D35: 66666666 | E35: =SUMIFS(Compras!N:N,Compras!G:G,$A$23,Compras!D:D,C35) -> 523533370 | F35: =SUMIFS(Facturado!Q:Q,Facturado!K:K,$A$23,Facturado!C:C,C35) -> 0 | G35: =IF(E35=0,F35,SUMIFS(Facturado!Q:Q,Facturado!K:K,$A$23,Facturado!C:C,C35,Facturado!H:H,"SI")) -> 0 | H35: =F35-G35 -> 0 | I35: =IF(H35<E35,E35-H35,0) -> 523533370
C36: SEPTIEMBRE | D36: 66666668 | E36: =SUMIFS(Compras!N:N,Compras!G:G,$A$23,Compras!D:D,C36) -> 8732512.2 | F36: =SUMIFS(Facturado!Q:Q,Facturado!K:K,$A$23,Facturado!C:C,C36) -> 1810630.2 | G36: =IF(E36=0,F36,SUMIFS(Facturado!Q:Q,Facturado!K:K,$A$23,Facturado!C:C,C36,Facturado!H:H,"SI")) -> 0 | H36: =F36-G36 -> 1810630.2
C37: TOTALES | D37: =SUM(D34:D36) -> 200000000 | F37: =SUM(F34:F36) -> 1810630.2
C38: MES | D38: META | E38: COMPRADO | F38: FACTURADO | G38: FACTURADO ANTERIOR | H38: FACTURADO Q | I38: PTE x FACTURAR | J38: BACK ORDER | K38: TOTAL Q4 | L38: % CUMPLIMIENTO Q1 | M38: TOTAL ELECTROBARRAS Q4
B39: Q4 | C39: OCTUBRE | D39: 66666666 | E39: =SUMIFS(Compras!N:N,Compras!G:G,$A$23,Compras!D:D,C39) -> 0 | F39: =SUMIFS(Facturado!Q:Q,Facturado!K:K,$A$23,Facturado!C:C,C39) -> 0 | G39: =IF(E39=0,F39,SUMIFS(Facturado!Q:Q,Facturado!K:K,$A$23,Facturado!C:C,C39,Facturado!H:H,"SI")) -> 0 | H39: =F39-G39 -> 0 | I39: =IF(H39<E39,E39-H39,0) -> 0 | J39: =I39+I40 -> 0 | K39: =IF(F42<D42,(F42+J39),F42) -> 0 | L39: =IFERROR(((K39/D42)*100)/100,0) -> 0 | M39: =SUMIFS(Facturado!Q:Q,Facturado!L:L,$A$23,Facturado!D:D,B39) -> 0
C40: NOVIEMBRE | D40: 66666666 | E40: =SUMIFS(Compras!N:N,Compras!G:G,$A$23,Compras!D:D,C40) -> 0 | F40: =SUMIFS(Facturado!Q:Q,Facturado!K:K,$A$23,Facturado!C:C,C40) -> 0 | G40: =IF(E40=0,F40,SUMIFS(Facturado!Q:Q,Facturado!K:K,$A$23,Facturado!C:C,C40,Facturado!H:H,"SI")) -> 0 | H40: =F40-G40 -> 0 | I40: =IF(H40<E40,E40-H40,0) -> 0
C41: DICIEMBRE | D41: 66666668 | E41: =SUMIFS(Compras!N:N,Compras!G:G,$A$23,Compras!D:D,C41) -> 0 | F41: =SUMIFS(Facturado!Q:Q,Facturado!K:K,$A$23,Facturado!C:C,C41) -> 0 | G41: =IF(E41=0,F41,SUMIFS(Facturado!Q:Q,Facturado!K:K,$A$23,Facturado!C:C,C41,Facturado!H:H,"SI")) -> 0 | H41: =F41-G41 -> 0
C42: TOTALES | D42: =SUM(D39:D41) -> 200000000 | F42: =SUM(F39:F41) -> 0
...

Sheet Facturado
A1: Factura | B1: Fecha Factura | C1: Mes | D1: Trimestre | E1: OC | F1: Fecha Compra | G1: Mes | H1: OC ANTIGUA | I1: Trimestre Compra | J1: Linea de negocio | K1: Categoria | L1: Subcategoria | M1: Producto | N1: Cantidad Facturada | O1: Moneda | P1: Precio Unitario | Q1: Subtotal | R1: Uso
A2: 673842 | B2: 46269 | C2: SEPTIEMBRE | D2: Q3 | E2: P01181 | F2: 46261.586 | G2: AGOSTO | H2: NO | I2: Q3 | J2: TELECOMUNICACIONES | K2: DC & DC | L2: ACCESORIOS | M2: [KP9999] Caja de escritorio de quorum, incluyeuna toma electrica precableada, tapa color negro | N2: 5 | O2: COP | P2: 303755.63 | Q2: 1518778.1 | R2: no
A3: 673841 | B3: 46269 | C3: SEPTIEMBRE | D3: Q3 | E3: P01134 | F3: 46212.505 | G3: JULIO | H3: NO | I3: Q3 | J3: TELECOMUNICACIONES | K3: DC & DC | L3: FIBRA ÓPTICA | M3: [32165] Bandeja de fibra 48 Fibras 1 RU Deslizable. Bandeja pre-armada para 48 Fibras Monomodo, Incluye: * Bandeja de protección de fusiones para 48 hilos * 2 prensaestopas para la entrada de la fibra óptica * Tornillos de Fijación * 24 Adaptadores duplex LC - LC | N3: 10 | O3: COP | P3: 194963.11 | Q3: 1949631.1 | R3: no
A4: 673840 | B4: 46269 | C4: SEPTIEMBRE | D4: Q3 | E4: P01108 | F4: 46190.654 | G4: JUNIO | H4: NO | I4: Q2 | J4: TELECOMUNICACIONES | K4: DC & DC | L4: FIBRA ÓPTICA | M4: [32165] Bandeja de fibra 48 Fibras 1 RU Deslizable. Bandeja pre-armada para 48 Fibras Monomodo, Incluye: * Bandeja de protección de fusiones para 48 hilos * 2 prensaestopas para la entrada de la fibra óptica * Tornillos de Fijación * 24 Adaptadores duplex LC - LC | N4: 15 | O4: COP | P4: 193859.22 | Q4: 2907888.3 | R4: no
A5: 673822 | B5: 46268 | C5: SEPTIEMBRE | D5: Q3 | E5: P01185 | F5: 46269.63 | G5: SEPTIEMBRE | H5: NO | I5: Q3 | J5: INDUSTRIAL | K5: ELECTROBARRAS | L5: ELECTROBARRAS | M5: [4419ZC] ELECTROBARRA MR MEDIA P MANUF Curva vertical + Conector 50401005+50400435 | N5: 1 | O5: COP | P5: 1810630.2 | Q5: 1810630.2 | R5: no
A6: 673810 | B6: 46268 | C6: SEPTIEMBRE | D6: Q3 | G6: ENERO | H6: NO | I6: Q1 | J6: TELECOMUNICACIONES | K6: DC & DC | L6: PATCH CORD | M6: [MC6A10-06] PATCH CORD CAT 6A, U/UTP, MOD8,10FT(3 METROS) AZUL | N6: 47 | O6: COP | P6: 58568.94 | Q6: 2752740.2 | R6: no
A7: 673797 | B7: 46268 | C7: SEPTIEMBRE | D7: Q3 | E7: P01141 | F7: 46255.552 | G7: AGOSTO | H7: NO | I7: Q3 | J7: POWER QUALITY | K7: DC & DC | M7: [ST15KT1DY] Transformador de Aislamiento de entrada | N7: 1 | O7: COP | P7: 10824848 | Q7: 10824848 | R7: no
A8: 673796 | B8: 46268 | C8: SEPTIEMBRE | D8: Q3 | E8: P01112 | F8: 46191.394 | G8: JUNIO | H8: NO | I8: Q2 | J8: INDUSTRIAL | K8: PHYSICAL SUPPORT | L8: DUCTO DLP | M8: [10785] Ángulo plano variable | N8: 10 | O8: COP | P8: 18995.04 | Q8: 189950.4 | R8: no
A9: 673795 | B9: 46268 | C9: SEPTIEMBRE | D9: Q3 | E9: P01031 | F9: 46126.404 | G9: ABRIL | H9: NO | I9: Q2 | J9: TELECOMUNICACIONES | K9: DC & DC | L9: PATCH CORD | M9: [MC6A10-06] PATCH CORD CAT 6A, U/UTP, MOD8,10FT(3 METROS) AZUL | N9: 47 | O9: COP | P9: 62384.05 | Q9: 2932050.4 | R9: no
A10: 673794 | B10: 46268 | C10: SEPTIEMBRE | D10: Q3 | E10: P00923 | F10: 46050.437 | G10: ENERO | H10: NO | I10: Q1 | J10: POWER QUALITY | K10: DC & DC | M10: [827055010000] UPS Forte de 10kVA a 208VAC | N10: 2 | O10: COP | P10: 14127103 | Q10: 28254207 | R10: no
A11: 673301 | B11: 46254 | C11: AGOSTO | D11: Q3 | E11: P01162 | F11: 46248.648 | G11: AGOSTO | H11: NO | I11: Q3 | J11: TELECOMUNICACIONES | K11: DC & DC | L11: ACCESORIOS | M11: [GBH19KIT] KIT DE BARRAJE HORIZONTAL PARA RACK DE 1"X19-1/4" | N11: 1 | O11: COP | P11: 275908.4 | Q11: 275908.4 | R11: no
A12: 673300 | B12: 46254 | C12: AGOSTO | D12: Q3 | E12: P01163 | F12: 46248.651 | G12: AGOSTO | H12: NO | I12: Q3 | J12: TELECOMUNICACIONES | K12: DC & DC | L12: JACKS | M12: [HDJS6A25] JACK HDJ, CATEGORÍA 6A, F/UTP - U/FTP - S/FTP. 100% METÁLICO, PRECIO POR PAQUETE DE 25 UNIDADES, INCLUYE HERRAMIENTA | N12: 25 | O12: COP | P12: 567850.02 | Q12: 14196250 | R12: no
A13: 673300 | B13: 46254 | C13: AGOSTO | D13: Q3 | E13: P01163 | F13: 46248.651 | G13: AGOSTO | H13: NO | I13: Q3 | J13: TELECOMUNICACIONES | K13: DC & DC | L13: ACCESORIOS | M13: [033684] Herraje Plano HD Modular 48 Puertos 1U. Incluye 4 modulos deslizables hacía adelante. NO incluye Jacks. Compatible con Jacks HDJ NO blindados, blindados y de fibra óptica. Color: Negro | N13: 29 | O13: COP | P13: 168321.39 | Q13: 4881320.3 | R13: no
A14: 673300 | B14: 46254 | C14: AGOSTO | D14: Q3 | E14: P01163 | F14: 46248.651 | G14: AGOSTO | H14: NO | I14: Q3 | J14: TELECOMUNICACIONES | K14: DC & DC | L14: ACCESORIOS | M14: [GB4X20TMGBKIT] Kit PBB / TMGB incluye: · Barraje GB4X20TMGB de 1/4" X 4" X 20". | N14: 1 | O14: COP | P14: 972008.18 | Q14: 972008.18 | R14: no
A15: 673299 | B15: 46254 | C15: AGOSTO | D15: Q3 | E15: P01126 | F15: 46209.643 | G15: JULIO | H15: NO | I15: Q3 | J15: TELECOMUNICACIONES | K15: DC & DC | L15: ACCESORIOS | M15: [GB2X10TGB] BARRAJE SECUNDARIO DE PUESTA A TIERRA TELECOMUNICACIONESSBB TGB DE 1/4" X 2" X10" INCLUYE AISLADORES Y ANTIOXIDANTE | N15: 4 | O15: COP | P15: 261177.52 | Q15: 1044710.1 | R15: no
A16: 673257 | B16: 46252 | C16: AGOSTO | D16: Q3 | E16: P01161 | F16: 46240.648 | G16: AGOSTO | H16: NO | I16: Q3 | J16: TELECOMUNICACIONES | K16: DC & DC | L16: ACCESORIOS | M16: [RFBA4R25] CAJA DE ACERO PARA CONCRETO DE 4 SALIDAS. COMPATIBLE CON TAPA FPB Y FPC | N16: 2 | O16: COP | P16: 693885.3 | Q16: 1387770.6 | R16: no
A17: 673256 | B17: 46252 | C17: AGOSTO | D17: Q3 | E17: P01149 | F17: 46227.399 | G17: JULIO | H17: NO | I17: Q3 | J17: TELECOMUNICACIONES | K17: DC & DC | L17: ACCESORIOS | M17: [RFBADEC] Accesorio para toma estilo decorador para cajas RFBA | N17: 6 | O17: COP | P17: 35594.12 | Q17: 213564.72 | R17: no
A18: 673255 | B18: 46252 | C18: AGOSTO | D18: Q3 | E18: P01123 | F18: 46196.441 | G18: JUNIO | H18: NO | I18: Q2 | J18: INDUSTRIAL | K18: PHYSICAL SUPPORT | L18: DUCTO DLP | M18: [10802] UNION PARA CUBIERTA DE DUCTO105x50 | N18: 10 | O18: COP | P18: 3909.41 | Q18: 39094.1 | R18: no
A19: 673254 | B19: 46252 | C19: AGOSTO | D19: Q3 | G19: ENERO | H19: NO | I19: Q1 | J19: INDUSTRIAL | K19: INDUSTRIAL | L19: BREAKERS | M19: [420720] DPX3 MAGN 250/200A 60KA/240V Interruptor de caja moldeada DPX³ 250 solo magnético fijo - 3P - Icu 36kA (400V~) - In 200A | N19: 1 | O19: COP | P19: 1243100 | Q19: 1243100 | R19: no
A20: 673133 | B20: 46248 | C20: AGOSTO | D20: Q3 | E20: P01108 | F20: 46190.654 | G20: JUNIO | H20: NO | I20: Q2 | J20: TELECOMUNICACIONES | K20: DC & DC | L20: ACCESORIOS | M20: [32162] BANDEJA 48 FIBRAS MULTIMODO 1RU DESLIZABLE INCLUYE: BANDEJA PORTA FUSIONES 24 HILOS, 2 PRENSA ESTOPA PARA ENTRADA FIBRA OPTICA, TORNILOS, 24 ADAPTADORES DUPLEX LC-LC | N20: 9 | O20: COP | P20: 192793.56 | Q20: 1735142 | R20: no
A21: 673134 | B21: 46248 | C21: AGOSTO | D21: Q3 | E21: P01134 | F21: 46212.505 | G21: JULIO | H21: NO | I21: Q3 | J21: TELECOMUNICACIONES | K21: DC & DC | L21: ACCESORIOS | M21: [32162] BANDEJA 48 FIBRAS MULTIMODO 1RU DESLIZABLE INCLUYE: BANDEJA PORTA FUSIONES 24 HILOS, 2 PRENSA ESTOPA PARA ENTRADA FIBRA OPTICA, TORNILOS, 24 ADAPTADORES DUPLEX LC-LC | N21: 5 | O21: COP | P21: 193891.43 | Q21: 969457.15 | R21: no
A22: 673022 | B22: 46245 | C22: AGOSTO | D22: Q3 | E22: P01085 | F22: 46169.653 | G22: MAYO | H22: NO | I22: Q2 | J22: INDUSTRIAL | K22: INDUSTRIAL | L22: CABLOFIL | M22: [CM000071] REJILLA CF54/100BSEZ TRAMO 3 METROS | N22: 10 | O22: COP | P22: 81730 | Q22: 817300 | R22: no
A23: 673022 | B23: 46245 | C23: AGOSTO | D23: Q3 | E23: P01085 | G23: ENERO | H23: NO | I23: Q1 | J23: INDUSTRIAL | K23: INDUSTRIAL | L23: CABLOFIL | M23: [CM000401] REJILLA-CF54/600BSEZ - BANDEJA | N23: 16 | O23: COP | P23: 250579.99 | Q23: 4009279.8 | R23: no
A24: 673021 | B24: 46245 | C24: AGOSTO | D24: Q3 | E24: P01108 | F24: 46190.654 | G24: JUNIO | H24: NO | I24: Q2 | J24: TELECOMUNICACIONES | K24: DC & DC | L24: ACCESORIOS | M24: [32162] BANDEJA 48 FIBRAS MULTIMODO 1RU DESLIZABLE INCLUYE: BANDEJA PORTA FUSIONES 24 HILOS, 2 PRENSA ESTOPA PARA ENTRADA FIBRA OPTICA, TORNILOS, 24 ADAPTADORES DUPLEX LC-LC | N24: 4 | O24: COP | P24: 194906.09 | Q24: 779624.36 | R24: no
A25: 672855 | B25: 46239 | C25: AGOSTO | D25: Q3 | E25: P01148 | F25: 46225.43 | G25: JULIO | H25: NO | I25: Q3 | J25: INDUSTRIAL | K25: INDUSTRIAL | M25: [3232-W] Tomacorriente dúplex blanca, 15 A 125 V | N25: 60 | O25: COP | P25: 2400 | Q25: 144000 | R25: no
A26: 672757 | B26: 46234 | C26: JULIO | D26: Q3 | E26: P01150 | F26: 46230.708 | G26: JULIO | H26: NO | I26: Q3 | J26: INDUSTRIAL | K26: INDUSTRIAL | L26: TOMAS ELECTRICAS | M26: [555439] TEMPRA P17 CLAVIJA 32A 3P+N+T 380-415V IP67 | N26: 6 | O26: COP | P26: 77347.48 | Q26: 464084.88 | R26: no
A27: 672756 | B27: 46234 | C27: JULIO | D27: Q3 | E27: P01149 | F27: 46227.399 | G27: JULIO | H27: NO | I27: Q3 | J27: TELECOMUNICACIONES | K27: DC & DC | L27: ACCESORIOS | M27: [RFBA4R25] CAJA DE ACERO PARA CONCRETO DE 4 SALIDAS. COMPATIBLE CON TAPA FPB Y FPC | N27: 2 | O27: COP | P27: 713733.62 | Q27: 1427467.2 | R27: no
A28: 672755 | B28: 46234 | C28: JULIO | D28: Q3 | E28: P01108 | F28: 46190.654 | G28: JUNIO | H28: NO | I28: Q2 | J28: TELECOMUNICACIONES | K28: DC & DC | L28: JACKS | M28: [KT2J6A-36] JACK KEYSTONE CAT 6A CLARITY U/UTP 10G AZUL | N28: 400 | O28: COP | P28: 15876.29 | Q28: 6350516 | R28: no
A29: 672754 | B29: 46234 | C29: JULIO | D29: Q3 | E29: P01112 | F29: 46191.394 | G29: JUNIO | H29: NO | I29: Q2 | J29: INDUSTRIAL | K29: PHYSICAL SUPPORT | L29: DUCTO DLP | M29: [10953] Marco plano para instalar 3 módulos | N29: 5 | O29: COP | P29: 11670.59 | Q29: 58352.95 | R29: no
A30: 672753 | B30: 46234 | C30: JULIO | D30: Q3 | E30: P01105 | F30: 46184.711 | G30: JUNIO | H30: NO | I30: Q2 | J30: TELECOMUNICACIONES | K30: DC & DC | L30: JACKS | M30: [076576] Jack categoría 6A para caja 684636, U/UTP - U/FTP - F/UTP - S/FTP, 10Gbps. Color: Blanco, Autoponchable | N30: 124 | O30: COP | P30: 17890.15 | Q30: 2218378.6 | R30: no
A31: 672752 | B31: 46234 | C31: JULIO | D31: Q3 | E31: P01041 | F31: 46129.363 | G31: ABRIL | H31: NO | I31: Q2 | J31: INDUSTRIAL | K31: INDUSTRIAL | L31: ACCESORIOS | M31: [CM923020-CL] SEPARADOR COT 50MM PERFIL SEP GS 50 GS - 3 Metros | N31: 120 | O31: COP | P31: 34320 | Q31: 4118400 | R31: no
A32: 672751 | B32: 46234 | C32: JULIO | D32: Q3 | E32: P01031 | F32: 46126.404 | G32: ABRIL | H32: NO | I32: Q2 | J32: TELECOMUNICACIONES | K32: DC & DC | L32: PATCH CORD | M32: [MC6A10-06] PATCH CORD CAT 6A, U/UTP, MOD8,10FT(3 METROS) AZUL | N32: 125 | O32: COP | P32: 62232.04 | Q32: 7779005 | R32: no
A33: 672280 | B33: 46220 | C33: JULIO | D33: Q3 | E33: P01136 | F33: 46217.367 | G33: JULIO | H33: NO | I33: Q3 | J33: TELECOMUNICACIONES | K33: DC & DC | L33: CONTENCIÓN TELCO | M33: [19-84-T4SDA2132] Rack Abierto de 4 postes, 45U, Color Negro. | N33: 1 | O33: COP | P33: 2575984 | Q33: 2575984 | R33: no
A34: 672280 | B34: 46220 | C34: JULIO | D34: Q3 | E34: P01136 | F34: 46217.367 | G34: JULIO | H34: NO | I34: Q3 | J34: TELECOMUNICACIONES | K34: DC & DC | L34: PDU | M34: [R8BZ] MULTITOMA PDU BASICA HORIZONTAL 120V 15A NEMA 5-15P 8 SALIDAS NEMA 5-15R SUPRESOR 13KA | N34: 1 | O34: COP | P34: 272768.91 | Q34: 272768.91 | R34: no
A35: 672280 | B35: 46220 | C35: JULIO | D35: Q3 | E35: P01136 | F35: 46217.367 | G35: JULIO | H35: NO | I35: Q3 | J35: TELECOMUNICACIONES | K35: DC & DC | L35: ACCESORIOS | M35: [GBH19KIT] KIT DE BARRAJE HORIZONTAL PARA RACK DE 1"X19-1/4" | N35: 1 | O35: COP | P35: 253201.68 | Q35: 253201.68 | R35: no
A36: 672279 | B36: 46220 | C36: JULIO | D36: Q3 | E36: P01137 | F36: 46213.477 | G36: JULIO | H36: NO | I36: Q3 | J36: TELECOMUNICACIONES | K36: DC & DC | L36: ACCESORIOS | M36: [HDPSC6A-5PKU] Plug de Ponchado en Campo RJ45 HD Categoría 6A S/FTP - F/UTP - U/FTP - U/UTP. Autoponchable. Unidad | N36: 40 | O36: COP | P36: 155945.76 | Q36: 6237830.4 | R36: no
A37: 672278 | B37: 46220 | C37: JULIO | D37: Q3 | E37: P01126 | F37: 46209.643 | G37: JULIO | H37: NO | I37: Q3 | J37: TELECOMUNICACIONES | K37: DC & DC | L37: ACCESORIOS | M37: [GB4X12J] Barraje Principal de Puesta a Tierra de Telecomunicaciones PBB / TMGB de diseño estándar de 1/4" X 4" X 12" | N37: 1 | O37: COP | P37: 413737.82 | Q37: 413737.82 | R37: no
... A39: 672277 | B39: 46220 | C39: JULIO | D39: Q3 | E39: P01105 | F39: 46184.711 | G39: JUNIO | H39: NO | I39: Q2 | J39: TELECOMUNICACIONES | K39: DC & DC | L39: FIBRA ÓPTICA | M39: [32141] Casete estándar para fusión de fibra óptica, capacidad 1 módulo de fibra óptica, incluye espacio para protectores de fusión para 24 fibras y 2 prensaestopas PG11, compatible | N39: 28 | O39: COP | P39: 108522.6 | Q39: 3038632.8 | R39: no
A40: 672218 | B40: 46217 | C40: JULIO | D40: Q3 | G40: ENERO | H40: NO | I40: Q1 | J40: POWER QUALITY | K40: DC & DC | M40: [310143] UPS DAKER DK 3000VA 120V UL CON BAT | N40: 82 | O40: COP | P40: 1956754.9 | Q40: 1.604539e+08 | R40: no
A41: 672217 | B41: 46217 | C41: JULIO | D41: Q3 | G41: ENERO | H41: NO | I41: Q1 | J41: INDUSTRIAL | K41: INDUSTRIAL | M41: [IG-8300] Tomacorriente duplex con polo a tierra aislado (IG) para computador, grado hospitalario, 20A - 125V AC, NEMA 5-20R | N41: 500 | O41: COP | P41: 19125 | Q41: 9562500 | R41: no
...

Sheet Compras
A1: Proveedor | B1: OC | C1: Fecha | D1: Mes | E1: Trimestre | F1: Linea de negocio | G1: Categoria | H1: Subcategoria | I1: Producto | J1: Cantidad Facturada | K1: Moneda | L1: Precio Unitario | M1: Subtotal | N1: Subtotal Real | O1: uso | P1: 3306.86
A2: LEGRAND COLOMBIA S.A | B2: P01197 | C2: 46279.476 | D2: SEPTIEMBRE | E2: Q3 | F2: INDUSTRIAL | G2: ELECTROBARRAS | H2: ELECTROBARRAS | I2: [60250100P] SCP 2N AL 630A E REC 3M | J2: 3 | K2: COP | L2: 2307294 | M2: 6921882 | N2: 6921882
A3: LEGRAND COLOMBIA S.A | B3: P01193 | C3: 46274.657 | D3: SEPTIEMBRE | E3: Q3 | F3: TELECOMUNICACIONES | G3: DC & DC | H3: ACCESORIOS | I3: [HDPSC6A-5PK] Plug de Ponchado en Campo RJ45 HD Categoría 6A S/FTP - F/UTP - U/FTP - U/UTP. Autoponchable. Precio por paquete 5 Und | J3: 176 | K3: USD | L3: 48 | M3: 8448 | N3: 27936353
A4: LEGRAND COLOMBIA S.A | B4: P01193 | C4: 46274.657 | D4: SEPTIEMBRE | E4: Q3 | F4: TELECOMUNICACIONES | G4: DC & DC | H4: CABLE UTP | I4: [LG-932746] Cable categoría 6A, U/UTP 500Mhz, 10G, 23AWG, color gris claro. PVC. Presentación carrete de 500 metros | J4: 14 | K4: USD | L4: 300 | M4: 4200 | N4: 13888812
A5: LEGRAND COLOMBIA S.A | B5: P01185 | C5: 46269.63 | D5: SEPTIEMBRE | E5: Q3 | F5: INDUSTRIAL | G5: ELECTROBARRAS | H5: ELECTROBARRAS | I5: [4419ZC] ELECTROBARRA MR MEDIA P MANUF Curva vertical + Conector 50401005+50400435 | J5: 1 | K5: COP | L5: 1810630.2 | M5: 1810630.2 | N5: 1810630.2
A6: LEGRAND COLOMBIA S.A | B6: P01184 | C6: 46268.641 | D6: SEPTIEMBRE | E6: Q3 | F6: TELECOMUNICACIONES | G6: DC & DC | H6: FIBRA ÓPTICA | I6: [572837] Adaptador para 1 Jack Keystone para Arteor. Color Magnesio. Incluye tapa guardapolvo, 2 Módulos | J6: 177 | K6: USD | L6: 5.42 | M6: 959.34 | N6: 3172403.1
A7: LEGRAND COLOMBIA S.A | B7: P01181 | C7: 46261.586 | D7: AGOSTO | E7: Q3 | F7: TELECOMUNICACIONES | G7: DC & DC | H7: ACCESORIOS | I7: [KP9999] Caja de escritorio de quorum, incluyeuna toma electrica precableada, tapa color negro | J7: 5 | K7: USD | L7: 97.06 | M7: 485.3 | N7: 1604819.2
A8: LEGRAND COLOMBIA S.A | B8: P01180 | C8: 46260.447 | D8: AGOSTO | E8: Q3 | F8: INDUSTRIAL | G8: ELECTROBARRAS | H8: ELECTROBARRAS | I8: [63281002P] XCP-HP Al 1000A board-trans feed RH std | J8: 1 | K8: COP | L8: 860931 | M8: 860931 | N8: 860931
A9: LEGRAND COLOMBIA S.A | B9: P01180 | C9: 46260.447 | D9: AGOSTO | E9: Q3 | F9: INDUSTRIAL | G9: ELECTROBARRAS | H9: ELECTROBARRAS | I9: [63280182P] XCP-HP Al 1000A feeder element L=2001-2500 | J9: 9 | K9: COP | L9: 1924320 | M9: 17318880 | N9: 17318880
A10: LEGRAND COLOMBIA S.A | B10: P01180 | C10: 46260.447 | D10: AGOSTO | E10: Q3 | F10: INDUSTRIAL | G10: ELECTROBARRAS | H10: ELECTROBARRAS | I10: [63280312P] XCPH ANG HZ STD IZ T1 1000A AL | J10: 3 | K10: COP | L10: 1036830 | M10: 3110490 | N10: 3110490
A11: LEGRAND COLOMBIA S.A | B11: P01180 | C11: 46260.447 | D11: AGOSTO | E11: Q3 | F11: INDUSTRIAL | G11: ELECTROBARRAS | H11: ELECTROBARRAS | I11: [63280102P] XCPH TR 3M 1000A AL | J11: 65 | K11: COP | L11: 2347260 | M11: 152571900 | N11: 152571900
A12: LEGRAND COLOMBIA S.A | B12: P01180 | C12: 46260.447 | D12: AGOSTO | E12: Q3 | F12: INDUSTRIAL | G12: ELECTROBARRAS | H12: ELECTROBARRAS | I12: [63280412P] XCPH ANG VE STD IZ T1 1000A AL | J12: 7 | K12: COP | L12: 1413600 | M12: 9895200 | N12: 9895200
A13: LEGRAND COLOMBIA S.A | B13: P01180 | C13: 46260.447 | D13: AGOSTO | E13: Q3 | F13: INDUSTRIAL | G13: ELECTROBARRAS | H13: ELECTROBARRAS | I13: [63280172P] XCPH TR 1-1,5M 1000A AL | J13: 11 | K13: COP | L13: 1244310 | M13: 13687410 | N13: 13687410
... A26: LEGRAND COLOMBIA S.A | B26: P01180 | C26: 46260.447 | D26: AGOSTO | E26: Q3 | F26: INDUSTRIAL | G26: ELECTROBARRAS | H26: ELECTROBARRAS | I26: [50484005-E] Caja SCP Plug-in T2, 250A | J26: 1 | K26: COP | L26: 1786380 | M26: 1786380 | N26: 1786380
A27: LEGRAND COLOMBIA S.A | B27: P01180 | C27: 46260.447 | D27: AGOSTO | E27: Q3 | F27: INDUSTRIAL | G27: INDUSTRIAL | I27: [27105] INTERRUP DRX 3P,250A,ICU 35KA | J27: 1 | K27: COP | L27: 0 | M27: 0 | N27: 0
A28: LEGRAND COLOMBIA S.A | B28: P01180 | C28: 46260.447 | D28: AGOSTO | E28: Q3 | F28: INDUSTRIAL | G28: ELECTROBARRAS | H28: ELECTROBARRAS | I28: [27125] Interruptor Termomagnético Fijo DRX_250, 3P, 150A, Icu 65KA/220V | J28: 1 | K28: COP | L28: 0 | M28: 0 | N28: 0
A29: LEGRAND COLOMBIA S.A | B29: P01180 | C29: 46260.447 | D29: AGOSTO | E29: Q3 | F29: INDUSTRIAL | G29: ELECTROBARRAS | H29: ELECTROBARRAS | I29: [50484003-E] Caja SCP Plug-in T1, 160A | J29: 1 | K29: COP | L29: 897700 | M29: 897700 | N29: 897700
A30: LEGRAND COLOMBIA S.A | B30: P01180 | C30: 46260.447 | D30: AGOSTO | E30: Q3 | F30: INDUSTRIAL | G30: ELECTROBARRAS | H30: ELECTROBARRAS | I30: [63280722P] XCP-HP Al 1000A horizontal T-element T3 | J30: 1 | K30: COP | L30: 4846642 | M30: 4846642 | N30: 4846642
A31: LEGRAND COLOMBIA S.A | B31: P01180 | C31: 46260.447 | D31: AGOSTO | E31: Q3 | F31: INDUSTRIAL | G31: ELECTROBARRAS | H31: ELECTROBARRAS | I31: [63280332P] XCPH ANG HZ ESP IZ T1 1000A AL | J31: 1 | K31: COP | L31: 1354320 | M31: 1354320 | N31: 1354320
A32: LEGRAND COLOMBIA S.A | B32: P01180 | C32: 46260.447 | D32: AGOSTO | E32: Q3 | F32: INDUSTRIAL | G32: ELECTROBARRAS | H32: ELECTROBARRAS | I32: [63281012P] XCPH CONE IZ T1 1000A AL | J32: 1 | K32: COP | L32: 1162800 | M32: 1162800 | N32: 1162800
A33: LEGRAND COLOMBIA S.A | B33: P01180 | C33: 46260.447 | D33: AGOSTO | E33: Q3 | F33: INDUSTRIAL | G33: ELECTROBARRAS | H33: ELECTROBARRAS | I33: [63281022P] XCP-HP Al 1000A board-trans feed RH | J33: 1 | K33: COP | L33: 1217400 | M33: 1217400 | N33: 1217400
A34: LEGRAND COLOMBIA S.A | B34: P01180 | C34: 46260.447 | D34: AGOSTO | E34: Q3 | F34: INDUSTRIAL | G34: ELECTROBARRAS | H34: ELECTROBARRAS | I34: [VSCP1000AAL] SCP R+V AL 3M 1000A 3L+N+PE E | J34: 3 | K34: COP | L34: 97356 | M34: 292068 | N34: 292068
A35: LEGRAND COLOMBIA S.A | B35: P01180 | C35: 46260.447 | D35: AGOSTO | E35: Q3 | F35: INDUSTRIAL | G35: ELECTROBARRAS | H35: ELECTROBARRAS | I35: [50484006] Descripcion no disponible | J35: 1 | K35: COP | L35: 1777445 | M35: 1777445 | N35: 1777445
A36: LEGRAND COLOMBIA S.A | B36: P01180 | C36: 46260.447 | D36: AGOSTO | E36: Q3 | F36: INDUSTRIAL | G36: ELECTROBARRAS | H36: ELECTROBARRAS | I36: [CAP1000A] CAPOTA ELECTROBARRA X 1MT 1000A | J36: 70 | K36: COP | L36: 601853 | M36: 42129710 | N36: 42129710
A37: LEGRAND COLOMBIA S.A | B37: P01180 | C37: 46260.447 | D37: AGOSTO | E37: Q3 | F37: INDUSTRIAL | G37: ELECTROBARRAS | H37: ELECTROBARRAS | I37: [50401008] MR UNID ALIME DEREC AL 500A | J37: 1 | K37: COP | L37: 629557 | M37: 629557 | N37: 629557
A38: LEGRAND COLOMBIA S.A | B38: P01180 | C38: 46260.447 | D38: AGOSTO | E38: Q3 | F38: INDUSTRIAL | G38: ELECTROBARRAS | H38: ELECTROBARRAS | I38: [50400128] MR REC AL 1.5-3M 500A 3L+N+PE | J38: 15 | K38: COP | L38: 1469771 | M38: 22046565 | N38: 22046565
A39: LEGRAND COLOMBIA S.A | B39: P01180 | C39: 46260.447 | D39: AGOSTO | E39: Q3 | F39: INDUSTRIAL | G39: ELECTROBARRAS | H39: ELECTROBARRAS | I39: [50400318] MR ANG HORIZ IZQ AL 500A | J39: 5 | K39: COP | L39: 913415 | M39: 4567075 | N39: 4567075
... A58: LEGRAND COLOMBIA S.A | B58: P01161 | C58: 46240.648 | D58: AGOSTO | E58: Q3 | F58: TELECOMUNICACIONES | G58: DC & DC | H58: ACCESORIOS | I58: [RFBADEC] Accesorio para toma estilo decorador para cajas RFBA | J58: 8 | K58: USD | L58: 11.35 | M58: 90.8 | N58: 300262.89
A59: LEGRAND COLOMBIA S.A | B59: P01150 | C59: 46230.708 | D59: JULIO | E59: Q3 | F59: INDUSTRIAL | G59: INDUSTRIAL | I59: [555439] TEMPRA P17 CLAVIJA 32A 3P+N+T 380-415V IP67 | J59: 6 | K59: COP | L59: 77340 | M59: 464040 | N59: 464040
A60: LEGRAND COLOMBIA S.A | B60: P01149 | C60: 46227.399 | D60: JULIO | E60: Q3 | F60: TELECOMUNICACIONES | G60: DC & DC | H60: ACCESORIOS | I60: [RFBA4R25] CAJA DE ACERO PARA CONCRETO DE 4 SALIDAS. COMPATIBLE CON TAPA FPB Y FPC | J60: 2 | K60: USD | L60: 222.01 | M60: 444.02 | N60: 1468312
A61: LEGRAND COLOMBIA S.A | B61: P01149 | C61: 46227.399 | D61: JULIO | E61: Q3 | F61: TELECOMUNICACIONES | G61: DC & DC | H61: ACCESORIOS | I61: [RFBADP] Accesorio para una toma doble ojo para cajas RFBA | J61: 2 | K61: USD | L61: 12.18 | M61: 24.36 | N61: 80555.11
A62: LEGRAND COLOMBIA S.A | B62: P01149 | C62: 46227.399 | D62: JULIO | E62: Q3 | F62: TELECOMUNICACIONES | G62: DC & DC | H62: ACCESORIOS | I62: [RFBADEC] Accesorio para toma estilo decorador para cajas RFBA | J62: 6 | K62: USD | L62: 11.35 | M62: 68.1 | N62: 225197.17
A63: LEGRAND COLOMBIA S.A | B63: P01148 | C63: 46225.43 | D63: JULIO | E63: Q3 | F63: INDUSTRIAL | G63: INDUSTRIAL | I63: [3232-W] Tomacorriente dúplex blanca, 15 A 125 V | J63: 60 | K63: COP | L63: 2400 | M63: 144000 | N63: 144000
A64: LEGRAND COLOMBIA S.A | B64: P01141 | C64: 46255.552 | D64: AGOSTO | E64: Q3 | F64: POWER QUALITY | G64: DC & DC | I64: [ST15KT1DY] Transformador de Aislamiento de entrada | J64: 1 | K64: USD | L64: 3350 | M64: 3350 | N64: 11077981
A65: LEGRAND COLOMBIA S.A | B65: P01141 | C65: 46255.552 | D65: AGOSTO | E65: Q3 | F65: POWER QUALITY | G65: DC & DC | I65: [GABBAT-579AH-DK] GAB EXT 20 BAT DK 5-7-9AH | J65: 4 | K65: USD | L65: 386 | M65: 1544 | N65: 5105791.8
A66: LEGRAND COLOMBIA S.A | B66: P01140 | C66: 46218.463 | D66: JULIO | E66: Q3 | F66: SERVICIOS | G66: DC & DC | I66: [981412] 10-60 KVA KEOR T EVO RECT CONTROL BOARD | J66: 1 | K66: USD | L66: 384.38 | M66: 384.38 | N66: 1271090.8
A67: LEGRAND COLOMBIA S.A | B67: P01137 | C67: 46213.477 | D67: JULIO | E67: Q3 | F67: TELECOMUNICACIONES | G67: DC & DC | H67: ACCESORIOS | I67: [HDPSC6A-5PK] Plug de Ponchado en Campo RJ45 HD Categoría 6A S/FTP - F/UTP - U/FTP - U/UTP. Autoponchable. | J67: 40 | K67: USD | L67: 48 | M67: 1920 | N67: 6349171.2
A68: LEGRAND COLOMBIA S.A | B68: P01136 | C68: 46217.367 | D68: JULIO | E68: Q3 | F68: TELECOMUNICACIONES | G68: DC & DC | H68: CONTENCIÓN TELCO | I68: [19-84-T4SDA2132] Rack Abierto de 4 postes, 45U, Color Negro. | J68: 1 | K68: USD | L68: 795.17 | M68: 795.17 | N68: 2629515.9
A69: LEGRAND COLOMBIA S.A | B69: P01136 | C69: 46217.367 | D69: JULIO | E69: Q3 | F69: TELECOMUNICACIONES | G69: DC & DC | H69: PDU | I69: [R8BZ] MULTITOMA PDU BASICA HORIZONTAL 120V 15A NEMA 5-15P 8 SALIDAS NEMA 5-15R SUPRESOR 13KA | J69: 1 | K69: USD | L69: 84.2 | M69: 84.2 | N69: 278437.61
A70: LEGRAND COLOMBIA S.A | B70: P01136 | C70: 46217.367 | D70: JULIO | E70: Q3 | F70: TELECOMUNICACIONES | G70: DC & DC | H70: ACCESORIOS | I70: [GBH19KIT] KIT DE BARRAJE HORIZONTAL PARA RACK DE 1"X19-1/4" | J70: 1 | K70: USD | L70: 78.16 | M70: 78.16 | N70: 258464.18
...
